<mujoco model="cart_pole">
    <!-- Simulation settings, NOTE: the timestep seemed to make a huge difference -->
    <option solver="Newton" timestep="0.02" iterations="1" ls_iterations="4"/>

    <!-- Inertia is computed from geometry -->
    <compiler inertiafromgeom="true" />

    <!-- Default properties -->
    <default>
        <joint armature="0.0" damping="0.3" limited="true" />
        <geom contype="0" friction="1.0 0.1 0.1" />
    </default>

    <!-- Memory settings (default is 1000) -->
    <size nstack="3000" />

    <worldbody>

        <!-- Origin -->
        <geom name="ball" pos="0 0 0.8" type="sphere" size="0.03" rgba="1.0 0.424 0.047 1"/>
        
        <!-- Rail -->
        <geom name="rail" pos="0 0 0.8" quat="0.707 0 0.707 0" type="capsule" size="0.02 1.5" rgba="0.8 0.8 0.8 0.5"/>

        <!-- Cart -->
        <body name="cart" pos="0 0 0.8">
            <geom name="cart" pos="0 0 0" size="0.2 0.1 0.1" type="box" rgba="0.3 0.3 0.3 0.7"/>
            <joint axis="1 0 0" limited="true" name="slider" pos="0 0 0.1" range="-1.5 1.5" type="slide" />

            <!-- Pole -->
            <body name="pole" pos="0 0 0">
                <geom name="pole" fromto="0 0 0 0.001 0 0.6" size="0.04 0.36" type="capsule" rgba="0.6 0.6 0.6 0.5"/>
                <joint axis="0 -1 0" name="hinge" pos="0 0 0" range="-inf inf" type="hinge" />
            </body>

        </body>

    </worldbody>

    <!-- Actuator -->
    <actuator>
        <motor name="slide" joint="slider" ctrllimited="true" ctrlrange="-1 1" gear="100"/>
    </actuator>

    <!-- default configuration (when you press "Load key" button) -->
    <keyframe>
        <key name="default" qpos="0 3.14" qvel="0 0" />
    </keyframe>

    <!-- Specify the light settings -->
    <asset>
        <texture type="skybox" builtin="flat" rgb1="0 0 0" rgb2="0 0 0" width="512" height="3072"/>
        <texture type="2d" name="groundplane" builtin="checker" mark="edge" rgb1="0.2 0.3 0.4" rgb2="0.1 0.2 0.3" markrgb="0.9 0.9 0.9" width="300" height="300"/>
        <material name="groundplane" texture="groundplane" texuniform="true" texrepeat="5 5" reflectance="0.2"/>
    </asset>

    <worldbody>
        <!-- Add light -->
        <light pos="1.0 0.5 0.0" dir="0 0 -1" directional="true"/>  
    
        <!-- Add the Floor -->
        <geom name="floor" size="0 0 0.05" type="plane" material="groundplane"/>
    </worldbody>

</mujoco>